Workbook

Sheet Dashboard
B2: Hardware DVT Execution Dashboard
B3: nRF5340 BLE Development Board (MDBT53-1M + RP2040 probe)
B5: Board / Session | C5: (fill in — yellow) | E5: Overall
B6: Revision | C6: Rev B | E6: Total tests | F6: =COUNTA(DVT_Master!$A$5:$A$202) -> 101
B7: Board S/N (FICR ID) | E7: Executed (P+F) | F7: =C14+C15 -> 0
B8: Tester | E8: Pass rate | F8: =IF(F7=0,"",C14/F7)
B9: Date started | E9: Completion | F9: =IF(F6=0,"",F7/F6) -> 0
B10: Firmware version | C10: DVT-Helper 1.0
E12: Subsystem | F12: Tests | G12: Pass | H12: Fail | I12: Blocked | J12: Not Run | K12: Done %
B13: Status | C13: Count | E13: VIS | F13: =COUNTIF(DVT_Master!$A$5:$A$202,$E13) -> 11 | G13: =COUNTIFS(DVT_Master!$A$5:$A$202,$E13,DVT_Master!$N$5:$N$202,"Pass") -> 0 | H13: =COUNTIFS(DVT_Master!$A$5:$A$202,$E13,DVT_Master!$N$5:$N$202,"Fail") -> 0 | I13: =COUNTIFS(DVT_Master!$A$5:$A$202,$E13,DVT_Master!$N$5:$N$202,"Blocked") -> 0 | J13: =COUNTIFS(DVT_Master!$A$5:$A$202,$E13,DVT_Master!$N$5:$N$202,"Not Run") -> 11 | K13: =IF(F13=0,"",(G13+H13)/F13) -> 0
B14: Pass | C14: =COUNTIF(DVT_Master!$N$5:$N$202,"Pass") -> 0 | E14: PRE | F14: =COUNTIF(DVT_Master!$A$5:$A$202,$E14) -> 13 | G14: =COUNTIFS(DVT_Master!$A$5:$A$202,$E14,DVT_Master!$N$5:$N$202,"Pass") -> 0 | H14: =COUNTIFS(DVT_Master!$A$5:$A$202,$E14,DVT_Master!$N$5:$N$202,"Fail") -> 0 | I14: =COUNTIFS(DVT_Master!$A$5:$A$202,$E14,DVT_Master!$N$5:$N$202,"Blocked") -> 0 | J14: =COUNTIFS(DVT_Master!$A$5:$A$202,$E14,DVT_Master!$N$5:$N$202,"Not Run") -> 13 | K14: =IF(F14=0,"",(G14+H14)/F14) -> 0
B15: Fail | C15: =COUNTIF(DVT_Master!$N$5:$N$202,"Fail") -> 0 | E15: PWR | F15: =COUNTIF(DVT_Master!$A$5:$A$202,$E15) -> 14 | G15: =COUNTIFS(DVT_Master!$A$5:$A$202,$E15,DVT_Master!$N$5:$N$202,"Pass") -> 0 | H15: =COUNTIFS(DVT_Master!$A$5:$A$202,$E15,DVT_Master!$N$5:$N$202,"Fail") -> 0 | I15: =COUNTIFS(DVT_Master!$A$5:$A$202,$E15,DVT_Master!$N$5:$N$202,"Blocked") -> 0 | J15: =COUNTIFS(DVT_Master!$A$5:$A$202,$E15,DVT_Master!$N$5:$N$202,"Not Run") -> 14 | K15: =IF(F15=0,"",(G15+H15)/F15) -> 0
B16: In Progress | C16: =COUNTIF(DVT_Master!$N$5:$N$202,"In Progress") -> 0 | E16: CHG | F16: =COUNTIF(DVT_Master!$A$5:$A$202,$E16) -> 6 | G16: =COUNTIFS(DVT_Master!$A$5:$A$202,$E16,DVT_Master!$N$5:$N$202,"Pass") -> 0 | H16: =COUNTIFS(DVT_Master!$A$5:$A$202,$E16,DVT_Master!$N$5:$N$202,"Fail") -> 0 | I16: =COUNTIFS(DVT_Master!$A$5:$A$202,$E16,DVT_Master!$N$5:$N$202,"Blocked") -> 0 | J16: =COUNTIFS(DVT_Master!$A$5:$A$202,$E16,DVT_Master!$N$5:$N$202,"Not Run") -> 6 | K16: =IF(F16=0,"",(G16+H16)/F16) -> 0
B17: Blocked | C17: =COUNTIF(DVT_Master!$N$5:$N$202,"Blocked") -> 0 | E17: BAT | F17: =COUNTIF(DVT_Master!$A$5:$A$202,$E17) -> 6 | G17: =COUNTIFS(DVT_Master!$A$5:$A$202,$E17,DVT_Master!$N$5:$N$202,"Pass") -> 0 | H17: =COUNTIFS(DVT_Master!$A$5:$A$202,$E17,DVT_Master!$N$5:$N$202,"Fail") -> 0 | I17: =COUNTIFS(DVT_Master!$A$5:$A$202,$E17,DVT_Master!$N$5:$N$202,"Blocked") -> 0 | J17: =COUNTIFS(DVT_Master!$A$5:$A$202,$E17,DVT_Master!$N$5:$N$202,"Not Run") -> 6 | K17: =IF(F17=0,"",(G17+H17)/F17) -> 0
B18: Not Run | C18: =COUNTIF(DVT_Master!$N$5:$N$202,"Not Run") -> 101 | E18: DBG | F18: =COUNTIF(DVT_Master!$A$5:$A$202,$E18) -> 10 | G18: =COUNTIFS(DVT_Master!$A$5:$A$202,$E18,DVT_Master!$N$5:$N$202,"Pass") -> 0 | H18: =COUNTIFS(DVT_Master!$A$5:$A$202,$E18,DVT_Master!$N$5:$N$202,"Fail") -> 0 | I18: =COUNTIFS(DVT_Master!$A$5:$A$202,$E18,DVT_Master!$N$5:$N$202,"Blocked") -> 0 | J18: =COUNTIFS(DVT_Master!$A$5:$A$202,$E18,DVT_Master!$N$5:$N$202,"Not Run") -> 10 | K18: =IF(F18=0,"",(G18+H18)/F18) -> 0
E19: NRF | F19: =COUNTIF(DVT_Master!$A$5:$A$202,$E19) -> 9 | G19: =COUNTIFS(DVT_Master!$A$5:$A$202,$E19,DVT_Master!$N$5:$N$202,"Pass") -> 0 | H19: =COUNTIFS(DVT_Master!$A$5:$A$202,$E19,DVT_Master!$N$5:$N$202,"Fail") -> 0 | I19: =COUNTIFS(DVT_Master!$A$5:$A$202,$E19,DVT_Master!$N$5:$N$202,"Blocked") -> 0 | J19: =COUNTIFS(DVT_Master!$A$5:$A$202,$E19,DVT_Master!$N$5:$N$202,"Not Run") -> 9 | K19: =IF(F19=0,"",(G19+H19)/F19) -> 0
E20: GPIO | F20: =COUNTIF(DVT_Master!$A$5:$A$202,$E20) -> 5 | G20: =COUNTIFS(DVT_Master!$A$5:$A$202,$E20,DVT_Master!$N$5:$N$202,"Pass") -> 0 | H20: =COUNTIFS(DVT_Master!$A$5:$A$202,$E20,DVT_Master!$N$5:$N$202,"Fail") -> 0 | I20: =COUNTIFS(DVT_Master!$A$5:$A$202,$E20,DVT_Master!$N$5:$N$202,"Blocked") -> 0 | J20: =COUNTIFS(DVT_Master!$A$5:$A$202,$E20,DVT_Master!$N$5:$N$202,"Not Run") -> 5 | K20: =IF(F20=0,"",(G20+H20)/F20) -> 0
E21: I2C | F21: =COUNTIF(DVT_Master!$A$5:$A$202,$E21) -> 5 | G21: =COUNTIFS(DVT_Master!$A$5:$A$202,$E21,DVT_Master!$N$5:$N$202,"Pass") -> 0 | H21: =COUNTIFS(DVT_Master!$A$5:$A$202,$E21,DVT_Master!$N$5:$N$202,"Fail") -> 0 | I21: =COUNTIFS(DVT_Master!$A$5:$A$202,$E21,DVT_Master!$N$5:$N$202,"Blocked") -> 0 | J21: =COUNTIFS(DVT_Master!$A$5:$A$202,$E21,DVT_Master!$N$5:$N$202,"Not Run") -> 5 | K21: =IF(F21=0,"",(G21+H21)/F21) -> 0
E22: IMEAS | F22: =COUNTIF(DVT_Master!$A$5:$A$202,$E22) -> 9 | G22: =COUNTIFS(DVT_Master!$A$5:$A$202,$E22,DVT_Master!$N$5:$N$202,"Pass") -> 0 | H22: =COUNTIFS(DVT_Master!$A$5:$A$202,$E22,DVT_Master!$N$5:$N$202,"Fail") -> 0 | I22: =COUNTIFS(DVT_Master!$A$5:$A$202,$E22,DVT_Master!$N$5:$N$202,"Blocked") -> 0 | J22: =COUNTIFS(DVT_Master!$A$5:$A$202,$E22,DVT_Master!$N$5:$N$202,"Not Run") -> 9 | K22: =IF(F22=0,"",(G22+H22)/F22) -> 0
E23: RF | F23: =COUNTIF(DVT_Master!$A$5:$A$202,$E23) -> 7 | G23: =COUNTIFS(DVT_Master!$A$5:$A$202,$E23,DVT_Master!$N$5:$N$202,"Pass") -> 0 | H23: =COUNTIFS(DVT_Master!$A$5:$A$202,$E23,DVT_Master!$N$5:$N$202,"Fail") -> 0 | I23: =COUNTIFS(DVT_Master!$A$5:$A$202,$E23,DVT_Master!$N$5:$N$202,"Blocked") -> 0 | J23: =COUNTIFS(DVT_Master!$A$5:$A$202,$E23,DVT_Master!$N$5:$N$202,"Not Run") -> 7 | K23: =IF(F23=0,"",(G23+H23)/F23) -> 0
E24: SYS | F24: =COUNTIF(DVT_Master!$A$5:$A$202,$E24) -> 6 | G24: =COUNTIFS(DVT_Master!$A$5:$A$202,$E24,DVT_Master!$N$5:$N$202,"Pass") -> 0 | H24: =COUNTIFS(DVT_Master!$A$5:$A$202,$E24,DVT_Master!$N$5:$N$202,"Fail") -> 0 | I24: =COUNTIFS(DVT_Master!$A$5:$A$202,$E24,DVT_Master!$N$5:$N$202,"Blocked") -> 0 | J24: =COUNTIFS(DVT_Master!$A$5:$A$202,$E24,DVT_Master!$N$5:$N$202,"Not Run") -> 6 | K24: =IF(F24=0,"",(G24+H24)/F24) -> 0
B27: Board disposition
B28: Sign-off / date

Sheet Instructions
B2: DVT Tracker — How to Use (and reuse for future revisions)
B4: Workflow per board
B5: 1. Fill the yellow cells on Dashboard (Revision, Board S/N = FICR Device ID from NRF-02, Tester, Date, FW version).
B6: 2. Work top-to-bottom on DVT_Master. VIS and PRE are gates: any failure there = do not apply power.
B7: 3. Numeric checks: type the measured number into "Actual Result" using the unit shown. "Tolerance Check" fills Pass/Fail automatically from Min/Max. Example: 3V3 check, Min 3.2 / Max 3.4 — type 3.31 and Tolerance Check shows Pass.
B8: 4. Text/visual checks (no Min/Max): set "Manual Status" directly.
B9: 5. "Final Status" = Manual Status if you set one, otherwise the automatic Tolerance Check. Setting Manual Status always wins (use it to override).
B10: 6. DMM shows OL? Type OL into Actual Result: text sorts above any number, so it passes min-only checks (e.g. > 1 MOhm) and correctly fails max-limited ones.
B11: 7. Log every failure in Issue_Log with the Test ID; set board disposition on the Dashboard when done.
B12: Cloning for the next board / revision
B13: • Next board, same rev: Save As, update the Dashboard yellow cells, set Manual Status column to "Not Run", clear Actual Result and Notes. Tolerance/Final recompute.
B14: • Next PCB revision: same, plus adjust Min/Max to the new plan. Limits here come from DVT_Plan_nRF5340_Board_RevB.docx v2.0 (2026-07-22); the Plan Ref column maps every row to the plan.
... B19: • Insert rows above row 5 on DVT_Master.

Sheet DVT_Master
A1: =Dashboard!B3 & " — " & Dashboard!C6 & " | Board S/N: " & Dashboard!C7 & " | Tester: " & Dashboard!C8 -> nRF5340 BLE Development Board (MDBT53-1M + RP2040 probe) — Rev B | Board S/N: | Tester:
A2: Ensure all VIS and PRE checks pass before applying power. Numeric result + Min/Max -> automatic verdict; Manual Status overrides.
A4: Subsystem | B4: Test Num | C4: Test ID | D4: Plan Ref | E4: Description / Procedure | F4: Expected Outcome (Text) | G4: Target Value | H4: Min Allowed | I4: Max Allowed | J4: Unit | K4: Actual Result | L4: Tolerance Check | M4: Manual Status | N4: Final Status | O4: Notes
A5: VIS | B5: 1 | C5: =IF(ISBLANK(A5),"",A5&"-"&TEXT(B5,"000")) -> VIS-001 | D5: VIS-01 | E5: Overall reflow quality under magnification: tombstones, missing 0402s, bridges (hot-plate build — check paste-starved corners first) | F5: None found | L5: =IF(OR(ISBLANK(K5),AND(ISBLANK(H5),ISBLANK(I5))),"",IF(AND(IF(ISBLANK(H5),TRUE(),K5>=H5),IF(ISBLANK(I5),TRUE(),K5<=I5)),"Pass","Fail")) | M5: Not Run | N5: =IF(AND(M5<>"Not Run",M5<>""),M5,IF(L5<>"",L5,"Not Run")) -> Not Run
A6: VIS | B6: 2 | C6: =IF(ISBLANK(A6),"",A6&"-"&TEXT(B6,"000")) -> VIS-002 | D6: VIS-02 | E6: D2, D3 (B5819WS) polarity: cathode line toward V_SYS on both (D2 cathode = pad toward U6; D3 cathode = pad toward board interior) | F6: Both correct | L6: =IF(OR(ISBLANK(K6),AND(ISBLANK(H6),ISBLANK(I6))),"",IF(AND(IF(ISBLANK(H6),TRUE(),K6>=H6),IF(ISBLANK(I6),TRUE(),K6<=I6)),"Pass","Fail")) | M6: Not Run | N6: =IF(AND(M6<>"Not Run",M6<>""),M6,IF(L6<>"",L6,"Not Run")) -> Not Run
A7: VIS | B7: 3 | C7: =IF(ISBLANK(A7),"",A7&"-"&TEXT(B7,"000")) -> VIS-003 | D7: VIS-03 | E7: Pin-1 / orientation vs silk: U1, U2, U3, U4, U5, U6, U7, U8, Q1, Q2, Q3 | F7: All correct | L7: =IF(OR(ISBLANK(K7),AND(ISBLANK(H7),ISBLANK(I7))),"",IF(AND(IF(ISBLANK(H7),TRUE(),K7>=H7),IF(ISBLANK(I7),TRUE(),K7<=I7)),"Pass","Fail")) | M7: Not Run | N7: =IF(AND(M7<>"Not Run",M7<>""),M7,IF(L7<>"",L7,"Not Run")) -> Not Run
A8: VIS | B8: 4 | C8: =IF(ISBLANK(A8),"",A8&"-"&TEXT(B8,"000")) -> VIS-004 | D8: VIS-04 | E8: U14 MDBT53-1M: aligned, castellations wetted, antenna end (left board edge) clean — no solder, flux, labels or debris in the keepout | F8: Clean | L8: =IF(OR(ISBLANK(K8),AND(ISBLANK(H8),ISBLANK(I8))),"",IF(AND(IF(ISBLANK(H8),TRUE(),K8>=H8),IF(ISBLANK(I8),TRUE(),K8<=I8)),"Pass","Fail")) | M8: Not Run | N8: =IF(AND(M8<>"Not Run",M8<>""),M8,IF(L8<>"",L8,"Not Run")) -> Not Run
A9: VIS | B9: 5 | C9: =IF(ISBLANK(A9),"",A9&"-"&TEXT(B9,"000")) -> VIS-005 | D9: VIS-05 | E9: Fine-pitch: U2 LQFN-56 0.4 mm, U4 WSON-8, U1 MSOP-10 — no bridges, fillets visible at pad edges | F9: Clean | L9: =IF(OR(ISBLANK(K9),AND(ISBLANK(H9),ISBLANK(I9))),"",IF(AND(IF(ISBLANK(H9),TRUE(),K9>=H9),IF(ISBLANK(I9),TRUE(),K9<=I9)),"Pass","Fail")) | M9: Not Run | N9: =IF(AND(M9<>"Not Run",M9<>""),M9,IF(L9<>"",L9,"Not Run")) -> Not Run
A10: VIS | B10: 6 | C10: =IF(ISBLANK(A10),"",A10&"-"&TEXT(B10,"000")) -> VIS-006 | D10: VIS-06 | E10: USB-C J1 (hand-soldered after reflow): 12 signal pins wetted, no bridges, shell legs filled | F10: Clean | L10: =IF(OR(ISBLANK(K10),AND(ISBLANK(H10),ISBLANK(I10))),"",IF(AND(IF(ISBLANK(H10),TRUE(),K10>=H10),IF(ISBLANK(I10),TRUE(),K10<=I10)),"Pass","Fail")) | M10: Not Run | N10: =IF(AND(M10<>"Not Run",M10<>""),M10,IF(L10<>"",L10,"Not Run")) -> Not Run
A11: VIS | B11: 7 | C11: =IF(ISBLANK(A11),"",A11&"-"&TEXT(B11,"000")) -> VIS-007 | D11: VIS-07 | E11: Through-hole H1/H2/J2/J5/SW1 seated flat, joints filled (H1/H2/J2 are kitted separately — not on the BOM) | F11: Seated, filled | L11: =IF(OR(ISBLANK(K11),AND(ISBLANK(H11),ISBLANK(I11))),"",IF(AND(IF(ISBLANK(H11),TRUE(),K11>=H11),IF(ISBLANK(I11),TRUE(),K11<=I11)),"Pass","Fail")) | M11: Not Run | N11: =IF(AND(M11<>"Not Run",M11<>""),M11,IF(L11<>"",L11,"Not Run")) -> Not Run
A12: VIS | B12: 8 | C12: =IF(ISBLANK(A12),"",A12&"-"&TEXT(B12,"000")) -> VIS-008 | D12: VIS-08 | E12: SW2/SW3/SW4 click mechanically; SW1 slides with a detent in both positions | F12: All OK | L12: =IF(OR(ISBLANK(K12),AND(ISBLANK(H12),ISBLANK(I12))),"",IF(AND(IF(ISBLANK(H12),TRUE(),K12>=H12),IF(ISBLANK(I12),TRUE(),K12<=I12)),"Pass","Fail")) | M12: Not Run | N12: =IF(AND(M12<>"Not Run",M12<>""),M12,IF(L12<>"",L12,"Not Run")) -> Not Run
A13: VIS | B13: 9 | C13: =IF(ISBLANK(A13),"",A13&"-"&TEXT(B13,"000")) -> VIS-009 | D13: VIS-09 | E13: C49/C50 (NFC tuning, bottom) NOT populated — DNI by design; the schematic '100 nF' value is a placeholder | F13: Both empty | L13: =IF(OR(ISBLANK(K13),AND(ISBLANK(H13),ISBLANK(I13))),"",IF(AND(IF(ISBLANK(H13),TRUE(),K13>=H13),IF(ISBLANK(I13),TRUE(),K13<=I13)),"Pass","Fail")) | M13: Not Run | N13: =IF(AND(M13<>"Not Run",M13<>""),M13,IF(L13<>"",L13,"Not Run")) -> Not Run
A14: VIS | B14: 10 | C14: =IF(ISBLANK(A14),"",A14&"-"&TEXT(B14,"000")) -> VIS-010 | D14: VIS-10 | E14: Silkscreen legible; FCC/ISED 'Contains' module marking present? (known Rev B gap — record the result) | F14: Record | L14: =IF(OR(ISBLANK(K14),AND(ISBLANK(H14),ISBLANK(I14))),"",IF(AND(IF(ISBLANK(H14),TRUE(),K14>=H14),IF(ISBLANK(I14),TRUE(),K14<=I14)),"Pass","Fail")) | M14: Not Run | N14: =IF(AND(M14<>"Not Run",M14<>""),M14,IF(L14<>"",L14,"Not Run")) -> Not Run
A15: VIS | B15: 11 | C15: =IF(ISBLANK(A15),"",A15&"-"&TEXT(B15,"000")) -> VIS-011 | D15: VIS-11 | E15: Breadboard fit: H1/H2 rows seat across a standard breadboard on 2.54 mm centers | F15: Seats cleanly | L15: =IF(OR(ISBLANK(K15),AND(ISBLANK(H15),ISBLANK(I15))),"",IF(AND(IF(ISBLANK(H15),TRUE(),K15>=H15),IF(ISBLANK(I15),TRUE(),K15<=I15)),"Pass","Fail")) | M15: Not Run | N15: =IF(AND(M15<>"Not Run",M15<>""),M15,IF(L15<>"",L15,"Not Run")) -> Not Run
A16: PRE | B16: 1 | C16: =IF(ISBLANK(A16),"",A16&"-"&TEXT(B16,"000")) -> PRE-001 | D16: PRE-01 | E16: Identify & mark pin 1s by continuity: J2 pin nearer U7.5 = LDO side (J2.1); H1.1 = +5V end (to F1); H2.1 = 3V3 end (to U6.5) | F16: Mapped + marked | L16: =IF(OR(ISBLANK(K16),AND(ISBLANK(H16),ISBLANK(I16))),"",IF(AND(IF(ISBLANK(H16),TRUE(),K16>=H16),IF(ISBLANK(I16),TRUE(),K16<=I16)),"Pass","Fail")) | M16: Not Run | N16: =IF(AND(M16<>"Not Run",M16<>""),M16,IF(L16<>"",L16,"Not Run")) -> Not Run
A17: PRE | B17: 2 | C17: =IF(ISBLANK(A17),"",A17&"-"&TEXT(B17,"000")) -> PRE-002 | D17: PRE-02 | E17: V_USB to GND resistance (probe C2 + pad) | F17: ~10 kOhm (R7), not < 1 k | G17: 10000 | H17: 1000 | J17: Ohm | L17: =IF(OR(ISBLANK(K17),AND(ISBLANK(H17),ISBLANK(I17))),"",IF(AND(IF(ISBLANK(H17),TRUE(),K17>=H17),IF(ISBLANK(I17),TRUE(),K17<=I17)),"Pass","Fail")) | M17: Not Run | N17: =IF(AND(M17<>"Not Run",M17<>""),M17,IF(L17<>"",L17,"Not Run")) -> Not Run
A18: PRE | B18: 3 | C18: =IF(ISBLANK(A18),"",A18&"-"&TEXT(B18,"000")) -> PRE-003 | D18: PRE-03 | E18: V_SYS to GND (probe D2.1 cathode pad) | F18: High / climbing | H18: 50000 | J18: Ohm | L18: =IF(OR(ISBLANK(K18),AND(ISBLANK(H18),ISBLANK(I18))),"",IF(AND(IF(ISBLANK(H18),TRUE(),K18>=H18),IF(ISBLANK(I18),TRUE(),K18<=I18)),"Pass","Fail")) | M18: Not Run | N18: =IF(AND(M18<>"Not Run",M18<>""),M18,IF(L18<>"",L18,"Not Run")) -> Not Run
A19: PRE | B19: 4 | C19: =IF(ISBLANK(A19),"",A19&"-"&TEXT(B19,"000")) -> PRE-004 | D19: PRE-04 | E19: 3V3_OTHER to GND (probe H2.1) | F19: > 5 kOhm and climbing | H19: 5000 | J19: Ohm | L19: =IF(OR(ISBLANK(K19),AND(ISBLANK(H19),ISBLANK(I19))),"",IF(AND(IF(ISBLANK(H19),TRUE(),K19>=H19),IF(ISBLANK(I19),TRUE(),K19<=I19)),"Pass","Fail")) | M19: Not Run | N19: =IF(AND(M19<>"Not Run",M19<>""),M19,IF(L19<>"",L19,"Not Run")) -> Not Run
A20: PRE | B20: 5 | C20: =IF(ISBLANK(A20),"",A20&"-"&TEXT(B20,"000")) -> PRE-005 | D20: PRE-05 | E20: 3V3_NRF to GND (probe J2.2 side) | F20: > 5 kOhm and climbing | H20: 5000 | J20: Ohm | L20: =IF(OR(ISBLANK(K20),AND(ISBLANK(H20),ISBLANK(I20))),"",IF(AND(IF(ISBLANK(H20),TRUE(),K20>=H20),IF(ISBLANK(I20),TRUE(),K20<=I20)),"Pass","Fail")) | M20: Not Run | N20: =IF(AND(M20<>"Not Run",M20<>""),M20,IF(L20<>"",L20,"Not Run")) -> Not Run
A21: PRE | B21: 6 | C21: =IF(ISBLANK(A21),"",A21&"-"&TEXT(B21,"000")) -> PRE-006 | D21: PRE-06 | E21: J2.1 to J2.2 with jumper REMOVED — the measured rail must only connect through J2 | F21: Open / > 1 MOhm | H21: 1000000 | J21: Ohm | L21: =IF(OR(ISBLANK(K21),AND(ISBLANK(H21),ISBLANK(I21))),"",IF(AND(IF(ISBLANK(H21),TRUE(),K21>=H21),IF(ISBLANK(I21),TRUE(),K21<=I21)),"Pass","Fail")) | M21: Not Run | N21: =IF(AND(M21<>"Not Run",M21<>""),M21,IF(L21<>"",L21,"Not Run")) -> Not Run
A22: PRE | B22: 7 | C22: =IF(ISBLANK(A22),"",A22&"-"&TEXT(B22,"000")) -> PRE-007 | D22: PRE-07 | E22: Diode mode V_USB to V_SYS (red D3.2, black D3.1): B5819WS forward | F22: 0.15-0.45 V | G22: 0.3 | H22: 0.15 | I22: 0.45 | J22: V | L22: =IF(OR(ISBLANK(K22),AND(ISBLANK(H22),ISBLANK(I22))),"",IF(AND(IF(ISBLANK(H22),TRUE(),K22>=H22),IF(ISBLANK(I22),TRUE(),K22<=I22)),"Pass","Fail")) | M22: Not Run | N22: =IF(AND(M22<>"Not Run",M22<>""),M22,IF(L22<>"",L22,"Not Run")) -> Not Run
A23: PRE | B23: 8 | C23: =IF(ISBLANK(A23),"",A23&"-"&TEXT(B23,"000")) -> PRE-008 | D23: PRE-08 | E23: Diode mode +5V input path (red H1.1, black D2.1): F1 + D2 forward | F23: 0.15-0.50 V | G23: 0.3 | H23: 0.15 | I23: 0.5 | J23: V | L23: =IF(OR(ISBLANK(K23),AND(ISBLANK(H23),ISBLANK(I23))),"",IF(AND(IF(ISBLANK(H23),TRUE(),K23>=H23),IF(ISBLANK(I23),TRUE(),K23<=I23)),"Pass","Fail")) | M23: Not Run | N23: =IF(AND(M23<>"Not Run",M23<>""),M23,IF(L23<>"",L23,"Not Run")) -> Not Run
A24: PRE | B24: 9 | C24: =IF(ISBLANK(A24),"",A24&"-"&TEXT(B24,"000")) -> PRE-009 | D24: PRE-09 | E24: Reverse diode checks: red D2.1, black H1.1 = OL; red D3.1, black D3.2 = OL | F24: OL both | L24: =IF(OR(ISBLANK(K24),AND(ISBLANK(H24),ISBLANK(I24))),"",IF(AND(IF(ISBLANK(H24),TRUE(),K24>=H24),IF(ISBLANK(I24),TRUE(),K24<=I24)),"Pass","Fail")) | M24: Not Run | N24: =IF(AND(M24<>"Not Run",M24<>""),M24,IF(L24<>"",L24,"Not Run")) -> Not Run
A25: PRE | B25: 10 | C25: =IF(ISBLANK(A25),"",A25&"-"&TEXT(B25,"000")) -> PRE-010 | D25: PRE-10 | E25: USB D+ to D- (D1 pads) and VBUS to D+/D-: no shorts | F25: OL / > 1 MOhm | H25: 1000000 | J25: Ohm | L25: =IF(OR(ISBLANK(K25),AND(ISBLANK(H25),ISBLANK(I25))),"",IF(AND(IF(ISBLANK(H25),TRUE(),K25>=H25),IF(ISBLANK(I25),TRUE(),K25<=I25)),"Pass","Fail")) | M25: Not Run | N25: =IF(AND(M25<>"Not Run",M25<>""),M25,IF(L25<>"",L25,"Not Run")) -> Not Run
A26: PRE | B26: 11 | C26: =IF(ISBLANK(A26),"",A26&"-"&TEXT(B26,"000")) -> PRE-011 | D26: PRE-11 | E26: Battery pins J5.1 to J5.2: no short; J5.2 (BATT-) to GND: not 0 Ohm (protection FETs unbiased) | F26: No short | L26: =IF(OR(ISBLANK(K26),AND(ISBLANK(H26),ISBLANK(I26))),"",IF(AND(IF(ISBLANK(H26),TRUE(),K26>=H26),IF(ISBLANK(I26),TRUE(),K26<=I26)),"Pass","Fail")) | M26: Not Run | N26: =IF(AND(M26<>"Not Run",M26<>""),M26,IF(L26<>"",L26,"Not Run")) -> Not Run
A27: PRE | B27: 12 | C27: =IF(ISBLANK(A27),"",A27&"-"&TEXT(B27,"000")) -> PRE-012 | D27: PRE-12 | E27: SWDIO (J4.2) and SWCLK (J4.4) to GND: no short. REST (H1.19) to GND: no short; ~0 Ohm only while SW4 held | F27: OK | L27: =IF(OR(ISBLANK(K27),AND(ISBLANK(H27),ISBLANK(I27))),"",IF(AND(IF(ISBLANK(H27),TRUE(),K27>=H27),IF(ISBLANK(I27),TRUE(),K27<=I27)),"Pass","Fail")) | M27: Not Run | N27: =IF(AND(M27<>"Not Run",M27<>""),M27,IF(L27<>"",L27,"Not Run")) -> Not Run
A28: PRE | B28: 13 | C28: =IF(ISBLANK(A28),"",A28&"-"&TEXT(B28,"000")) -> PRE-013 | D28: PRE-13 | E28: TP3 to GND continuity ~0 Ohm (confirms map TP1=NFC1, TP2=NFC2, TP3=GND); TP1/TP2 NOT shorted to GND | F28: Confirmed | L28: =IF(OR(ISBLANK(K28),AND(ISBLANK(H28),ISBLANK(I28))),"",IF(AND(IF(ISBLANK(H28),TRUE(),K28>=H28),IF(ISBLANK(I28),TRUE(),K28<=I28)),"Pass","Fail")) | M28: Not Run | N28: =IF(AND(M28<>"Not Run",M28<>""),M28,IF(L28<>"",L28,"Not Run")) -> Not Run
A29: PWR | B29: 1 | C29: =IF(ISBLANK(A29),"",A29&"-"&TEXT(B29,"000")) -> PWR-001 | D29: PWR-01 | E29: First power: bench PSU 5.00 V, 100 mA CC limit, + to H1.1, - to H1.2 (GND). Supply current after 5 s | F29: Stable, no CC trip | G29: 20 | H29: 2 | I29: 60 | J29: mA | L29: =IF(OR(ISBLANK(K29),AND(ISBLANK(H29),ISBLANK(I29))),"",IF(AND(IF(ISBLANK(H29),TRUE(),K29>=H29),IF(ISBLANK(I29),TRUE(),K29<=I29)),"Pass","Fail")) | M29: Not Run | N29: =IF(AND(M29<>"Not Run",M29<>""),M29,IF(L29<>"",L29,"Not Run")) -> Not Run
A30: PWR | B30: 2 | C30: =IF(ISBLANK(A30),"",A30&"-"&TEXT(B30,"000")) -> PWR-002 | D30: PWR-02 | E30: Nothing hot after 60 s at first power (finger/IR: U6, U7, U2, U14) | F30: Cool / barely warm | L30: =IF(OR(ISBLANK(K30),AND(ISBLANK(H30),ISBLANK(I30))),"",IF(AND(IF(ISBLANK(H30),TRUE(),K30>=H30),IF(ISBLANK(I30),TRUE(),K30<=I30)),"Pass","Fail")) | M30: Not Run | N30: =IF(AND(M30<>"Not Run",M30<>""),M30,IF(L30<>"",L30,"Not Run")) -> Not Run
A31: PWR | B31: 3 | C31: =IF(ISBLANK(A31),"",A31&"-"&TEXT(B31,"000")) -> PWR-003 | D31: PWR-03 | E31: V_SYS (D2.1) = PSU minus F1 + D2 drop | F31: 4.3-4.9 V | G31: 4.6 | H31: 4.3 | I31: 4.9 | J31: V | L31: =IF(OR(ISBLANK(K31),AND(ISBLANK(H31),ISBLANK(I31))),"",IF(AND(IF(ISBLANK(H31),TRUE(),K31>=H31),IF(ISBLANK(I31),TRUE(),K31<=I31)),"Pass","Fail")) | M31: Not Run | N31: =IF(AND(M31<>"Not Run",M31<>""),M31,IF(L31<>"",L31,"Not Run")) -> Not Run
A32: PWR | B32: 4 | C32: =IF(ISBLANK(A32),"",A32&"-"&TEXT(B32,"000")) -> PWR-004 | D32: PWR-04 | E32: 3V3_OTHER at H2.1 | F32: 3.20-3.40 V | G32: 3.3 | H32: 3.2 | I32: 3.4 | J32: V | L32: =IF(OR(ISBLANK(K32),AND(ISBLANK(H32),ISBLANK(I32))),"",IF(AND(IF(ISBLANK(H32),TRUE(),K32>=H32),IF(ISBLANK(I32),TRUE(),K32<=I32)),"Pass","Fail")) | M32: Not Run | N32: =IF(AND(M32<>"Not Run",M32<>""),M32,IF(L32<>"",L32,"Not Run")) -> Not Run
A33: PWR | B33: 5 | C33: =IF(ISBLANK(A33),"",A33&"-"&TEXT(B33,"000")) -> PWR-005 | D33: PWR-05 | E33: 3V3_NRF at J2.2 (jumper fitted) | F33: 3.20-3.40 V | G33: 3.3 | H33: 3.2 | I33: 3.4 | J33: V | L33: =IF(OR(ISBLANK(K33),AND(ISBLANK(H33),ISBLANK(I33))),"",IF(AND(IF(ISBLANK(H33),TRUE(),K33>=H33),IF(ISBLANK(I33),TRUE(),K33<=I33)),"Pass","Fail")) | M33: Not Run | N33: =IF(AND(M33<>"Not Run",M33<>""),M33,IF(L33<>"",L33,"Not Run")) -> Not Run
A34: PWR | B34: 6 | C34: =IF(ISBLANK(A34),"",A34&"-"&TEXT(B34,"000")) -> PWR-006 | D34: PWR-06 | E34: J2 jumper contact drop: V(J2.1) - V(J2.2) | F34: <= 5 mV | I34: 5 | J34: mV | L34: =IF(OR(ISBLANK(K34),AND(ISBLANK(H34),ISBLANK(I34))),"",IF(AND(IF(ISBLANK(H34),TRUE(),K34>=H34),IF(ISBLANK(I34),TRUE(),K34<=I34)),"Pass","Fail")) | M34: Not Run | N34: =IF(AND(M34<>"Not Run",M34<>""),M34,IF(L34<>"",L34,"Not Run")) -> Not Run
A35: PWR | B35: 7 | C35: =IF(ISBLANK(A35),"",A35&"-"&TEXT(B35,"000")) -> PWR-007 | D35: PWR-07 | E35: Remove PSU. First USB power through inline USB meter, SW1 = DEBUG: V_USB | F35: 4.75-5.25 V | G35: 5 | H35: 4.75 | I35: 5.25 | J35: V | L35: =IF(OR(ISBLANK(K35),AND(ISBLANK(H35),ISBLANK(I35))),"",IF(AND(IF(ISBLANK(H35),TRUE(),K35>=H35),IF(ISBLANK(I35),TRUE(),K35<=I35)),"Pass","Fail")) | M35: Not Run | N35: =IF(AND(M35<>"Not Run",M35<>""),M35,IF(L35<>"",L35,"Not Run")) -> Not Run
A36: PWR | B36: 8 | C36: =IF(ISBLANK(A36),"",A36&"-"&TEXT(B36,"000")) -> PWR-008 | D36: PWR-08 | E36: USB idle input current (blank chips: RP2040 in BOOTSEL ROM, nRF blank) | F36: Record | H36: 5 | I36: 100 | J36: mA | L36: =IF(OR(ISBLANK(K36),AND(ISBLANK(H36),ISBLANK(I36))),"",IF(AND(IF(ISBLANK(H36),TRUE(),K36>=H36),IF(ISBLANK(I36),TRUE(),K36<=I36)),"Pass","Fail")) | M36: Not Run | N36: =IF(AND(M36<>"Not Run",M36<>""),M36,IF(L36<>"",L36,"Not Run")) -> Not Run
A37: PWR | B37: 9 | C37: =IF(ISBLANK(A37),"",A37&"-"&TEXT(B37,"000")) -> PWR-009 | D37: PWR-09 | E37: RPI-RP2 mass-storage device enumerates (blank U3 -> ROM bootloader; also proves X1 12 MHz and the FSUSB42 DEBUG path) | F37: Enumerates | L37: =IF(OR(ISBLANK(K37),AND(ISBLANK(H37),ISBLANK(I37))),"",IF(AND(IF(ISBLANK(H37),TRUE(),K37>=H37),IF(ISBLANK(I37),TRUE(),K37<=I37)),"Pass","Fail")) | M37: Not Run | N37: =IF(AND(M37<>"Not Run",M37<>""),M37,IF(L37<>"",L37,"Not Run")) -> Not Run
A38: PWR | B38: 10 | C38: =IF(ISBLANK(A38),"",A38&"-"&TEXT(B38,"000")) -> PWR-010 | D38: PWR-10 | E38: SW1 to APP: RPI-RP2 disappears (bus routed to blank nRF, no device). Back to DEBUG: reappears | F38: Behaves | L38: =IF(OR(ISBLANK(K38),AND(ISBLANK(H38),ISBLANK(I38))),"",IF(AND(IF(ISBLANK(H38),TRUE(),K38>=H38),IF(ISBLANK(I38),TRUE(),K38<=I38)),"Pass","Fail")) | M38: Not Run | N38: =IF(AND(M38<>"Not Run",M38<>""),M38,IF(L38<>"",L38,"Not Run")) -> Not Run
A39: PWR | B39: 11 | C39: =IF(ISBLANK(A39),"",A39&"-"&TEXT(B39,"000")) -> PWR-011 | D39: PWR-11 | E39: LED2 (green) on whenever V_SYS is present, off when unpowered | F39: Correct | L39: =IF(OR(ISBLANK(K39),AND(ISBLANK(H39),ISBLANK(I39))),"",IF(AND(IF(ISBLANK(H39),TRUE(),K39>=H39),IF(ISBLANK(I39),TRUE(),K39<=I39)),"Pass","Fail")) | M39: Not Run | N39: =IF(AND(M39<>"Not Run",M39<>""),M39,IF(L39<>"",L39,"Not Run")) -> Not Run
A40: PWR | B40: 12 | C40: =IF(ISBLANK(A40),"",A40&"-"&TEXT(B40,"000")) -> PWR-012 | D40: PWR-12 | E40: Backdrive: USB powered, voltage at H1.1 (+5V pin) — D2 blocks; the pin is input-only | F40: ~0 V | I40: 0.5 | J40: V | L40: =IF(OR(ISBLANK(K40),AND(ISBLANK(H40),ISBLANK(I40))),"",IF(AND(IF(ISBLANK(H40),TRUE(),K40>=H40),IF(ISBLANK(I40),TRUE(),K40<=I40)),"Pass","Fail")) | M40: Not Run | N40: =IF(AND(M40<>"Not Run",M40<>""),M40,IF(L40<>"",L40,"Not Run")) -> Not Run
A41: PWR | B41: 13 | C41: =IF(ISBLANK(A41),"",A41&"-"&TEXT(B41,"000")) -> PWR-013 | D41: PWR-13 | E41: Ripple (scope, optional): 3V3_OTHER and 3V3_NRF at idle | F41: < 30 mVpp, record | I41: 30 | J41: mVpp | L41: =IF(OR(ISBLANK(K41),AND(ISBLANK(H41),ISBLANK(I41))),"",IF(AND(IF(ISBLANK(H41),TRUE(),K41>=H41),IF(ISBLANK(I41),TRUE(),K41<=I41)),"Pass","Fail")) | M41: Not Run | N41: =IF(AND(M41<>"Not Run",M41<>""),M41,IF(L41<>"",L41,"Not Run")) -> Not Run
...

Sheet Issue_Log
B2: Issue Log
B4: # | C4: Test ID | D4: Description of failure | E4: Severity | F4: Found (date) | G4: Disposition / fix | H4: Status
B5: 1 | C5: PRE-000 | D5: (example row — replace) R40/R41 confirmed absent from assembly kit | E5: Major | F5: 2026-07 | G5: Hand-fit 2x 4.7 k 0402 before I2C section | H5: Example

Sheet Reference_Data
B2: Probe Point Quick Reference (top view, origin = board lower-left; all mm)
B4: Net | C4: Probe at | D4: Side | E4: Notes
B5: GND | C5: Any header GND / J1 shell | D5: Top | E5: H1.2/8/12/16, H2.2/8/13/19; TP3 (15.9, 5.4)
B6: V_USB | C6: C2 + pad | D6: Top | E6: 50.9, 9.3 (10 uF); also F1.1 side, LED1.2 (64.2, 16.6)
B7: V_SYS | C7: D2 cathode (D2.1) | D7: Top | E7: 47.5, 6.3; also D3.1 (55.3, 12.0), U6/U7 pin 1
B8: 3V3_OTHER | C8: H2.1 header pin | D8: Top | E8: 28.1 row, y=24.1, 3V3 end; also C3.2, U6.5
B9: 3V3_NRF | C9: J2.2 (rail side) | D9: Top | E9: J2 at 45.1, 21.5 — pin nearer U7 = LDO side J2.1 (PRE-01)
B10: LDO out (pre-J2) | C10: C11 + pad | D10: Top | E10: 45.8, 19.0 (1 uF on U7 output = J2.1 net)
B11: BATT+ | C11: C12 + pad | D11: Top | E11: 50.1, 21.9 (47 uF bulk)
B12: BATT- | C12: J5.2 / C13 | D12: Top | E12: J5 at 57.9, 21.6; C13 at 61.2, 16.4 (cell negative, not GND)
B13: +5V in | C13: H1.1 | D13: Top | E13: +5V end of H1 (y=1.3), before F1 (50.9, 4.9)
B14: USB D+ / D- | C14: D1 pads | D14: Top | E14: 54.5, 5.4 (USBLC6); connector-side pair
B15: Charger STAT | C15: U5 pin 1 / R6 | D15: Top | E15: U5 at 52.9, 16.8
... B20: nRF reset | C20: H1.19 / SW4 | D20: Top | E20: SW4 at 8.6, 21.2
B23: Header Pinout (as built, fab 2026-07-04; pin 1 = +5V end on H1, 3V3 end on H2)
B25: Pin | C25: H1 (bottom edge, y=1.3) | D25: H2 (top edge, y=24.1)
B26: 1 | C26: +5V (input only, via F1+D2) | D26: 3V3 (3V3_OTHER)
B27: 2 | C27: GND | D27: GND
B28: 3 | C28: P0.29 | D28: P0.11
B29: 4 | C29: P0.07 / AIN3 | D29: P0.12
B30: 5 | C30: P0.25 / AIN4 | D30: P0.05 / AIN1
B31: 6 | C31: P0.26 / AIN5 | D31: P0.06 / AIN2
B32: 7 | C32: P0.27 / AIN6 | D32: P0.04 / AIN0
B33: 8 | C33: GND | D33: GND
B34: 9 | C34: P0.10 | D34: P1.00
B35: 10 | C35: P0.09 | D35: P1.15
B36: 11 | C36: P0.08 | D36: P1.14
B37: 12 | C37: GND | D37: P1.12
... B44: 19 | C44: REST (nRF reset) | D44: GND
B46: UART nets are nRF-perspective: the probe (RP2040 GPIO4) drives P0.22/RX; nRF transmits on P0.20/TX = H1.15. External adapter: RX->H1.15 observe-only; do not drive H1.14 against the probe.
